[2022-04-13 21:53:56,344] {taskinstance.py:1032} INFO - Dependencies all met for <TaskInstance: LocalIngestionDAG.wget scheduled__2021-11-02T06:00:11+00:00 [queued]>
[2022-04-13 21:53:56,371] {taskinstance.py:1032} INFO - Dependencies all met for <TaskInstance: LocalIngestionDAG.wget scheduled__2021-11-02T06:00:11+00:00 [queued]>
[2022-04-13 21:53:56,372] {taskinstance.py:1238} INFO - 
--------------------------------------------------------------------------------
[2022-04-13 21:53:56,373] {taskinstance.py:1239} INFO - Starting attempt 1 of 1
[2022-04-13 21:53:56,374] {taskinstance.py:1240} INFO - 
--------------------------------------------------------------------------------
[2022-04-13 21:53:56,409] {taskinstance.py:1259} INFO - Executing <Task(BashOperator): wget> on 2021-11-02 06:00:11+00:00
[2022-04-13 21:53:56,416] {standard_task_runner.py:52} INFO - Started process 6786 to run task
[2022-04-13 21:53:56,424] {standard_task_runner.py:76} INFO - Running: ['***', 'tasks', 'run', 'LocalIngestionDAG', 'wget', 'scheduled__2021-11-02T06:00:11+00:00', '--job-id', '1326', '--raw', '--subdir', 'DAGS_FOLDER/data_ingestion_local.py', '--cfg-path', '/tmp/tmpmob98hbu', '--error-file', '/tmp/tmp5tf1svke']
[2022-04-13 21:53:56,426] {standard_task_runner.py:77} INFO - Job 1326: Subtask wget
[2022-04-13 21:53:56,548] {logging_mixin.py:109} INFO - Running <TaskInstance: LocalIngestionDAG.wget scheduled__2021-11-02T06:00:11+00:00 [running]> on host 13db72185839
[2022-04-13 21:53:56,671] {taskinstance.py:1426} INFO - Exporting the following env vars:
AIRFLOW_CTX_DAG_OWNER=***
AIRFLOW_CTX_DAG_ID=LocalIngestionDAG
AIRFLOW_CTX_TASK_ID=wget
AIRFLOW_CTX_EXECUTION_DATE=2021-11-02T06:00:11+00:00
AIRFLOW_CTX_DAG_RUN_ID=scheduled__2021-11-02T06:00:11+00:00
[2022-04-13 21:53:56,672] {subprocess.py:62} INFO - Tmp dir root location: 
 /tmp
[2022-04-13 21:53:56,675] {subprocess.py:74} INFO - Running command: ['bash', '-c', 'curl -sSL https://s3.amazonaws.com/nyc-tlc/trip+data/yellow_tripdata_2021-01.csv > /opt/***/output.csv']
[2022-04-13 21:53:56,691] {subprocess.py:85} INFO - Output:
[2022-04-13 22:15:17,128] {local_task_job.py:212} WARNING - State of this instance has been externally set to restarting. Terminating instance.
[2022-04-13 22:15:17,159] {process_utils.py:124} INFO - Sending Signals.SIGTERM to group 6786. PIDs of all processes in the group: [6787, 6789, 6786]
[2022-04-13 22:15:17,162] {process_utils.py:75} INFO - Sending the signal Signals.SIGTERM to group 6786
[2022-04-13 22:15:17,198] {taskinstance.py:1408} ERROR - Received SIGTERM. Terminating subprocesses.
[2022-04-13 22:15:17,231] {subprocess.py:99} INFO - Sending SIGTERM signal to process group
[2022-04-13 22:15:17,827] {taskinstance.py:1700} ERROR - Task failed with exception
Traceback (most recent call last):
  File "/home/airflow/.local/lib/python3.7/site-packages/airflow/models/taskinstance.py", line 1329, in _run_raw_task
    self._execute_task_with_callbacks(context)
  File "/home/airflow/.local/lib/python3.7/site-packages/airflow/models/taskinstance.py", line 1455, in _execute_task_with_callbacks
    result = self._execute_task(context, self.task)
  File "/home/airflow/.local/lib/python3.7/site-packages/airflow/models/taskinstance.py", line 1511, in _execute_task
    result = execute_callable(context=context)
  File "/home/airflow/.local/lib/python3.7/site-packages/airflow/operators/bash.py", line 182, in execute
    cwd=self.cwd,
  File "/home/airflow/.local/lib/python3.7/site-packages/airflow/hooks/subprocess.py", line 87, in run_command
    for raw_line in iter(self.sub_process.stdout.readline, b''):
  File "/home/airflow/.local/lib/python3.7/site-packages/airflow/models/taskinstance.py", line 1410, in signal_handler
    raise AirflowException("Task received SIGTERM signal")
airflow.exceptions.AirflowException: Task received SIGTERM signal
[2022-04-13 22:15:17,868] {taskinstance.py:1277} INFO - Marking task as UP_FOR_RETRY. dag_id=LocalIngestionDAG, task_id=wget, execution_date=20211102T060011, start_date=20220413T215356, end_date=20220413T221517
[2022-04-13 22:15:17,872] {process_utils.py:70} INFO - Process psutil.Process(pid=6789, status='terminated', started='21:53:55') (6789) terminated with exit code None
[2022-04-13 22:15:18,031] {standard_task_runner.py:92} ERROR - Failed to execute job 1326 for task wget
Traceback (most recent call last):
  File "/home/airflow/.local/lib/python3.7/site-packages/airflow/task/task_runner/standard_task_runner.py", line 85, in _start_by_fork
    args.func(args, dag=self.dag)
  File "/home/airflow/.local/lib/python3.7/site-packages/airflow/cli/cli_parser.py", line 48, in command
    return func(*args, **kwargs)
  File "/home/airflow/.local/lib/python3.7/site-packages/airflow/utils/cli.py", line 92, in wrapper
    return f(*args, **kwargs)
  File "/home/airflow/.local/lib/python3.7/site-packages/airflow/cli/commands/task_command.py", line 298, in task_run
    _run_task_by_selected_method(args, dag, ti)
  File "/home/airflow/.local/lib/python3.7/site-packages/airflow/cli/commands/task_command.py", line 107, in _run_task_by_selected_method
    _run_raw_task(args, ti)
  File "/home/airflow/.local/lib/python3.7/site-packages/airflow/cli/commands/task_command.py", line 184, in _run_raw_task
    error_file=args.error_file,
  File "/home/airflow/.local/lib/python3.7/site-packages/airflow/utils/session.py", line 70, in wrapper
    return func(*args, session=session, **kwargs)
  File "/home/airflow/.local/lib/python3.7/site-packages/airflow/models/taskinstance.py", line 1329, in _run_raw_task
    self._execute_task_with_callbacks(context)
  File "/home/airflow/.local/lib/python3.7/site-packages/airflow/models/taskinstance.py", line 1455, in _execute_task_with_callbacks
    result = self._execute_task(context, self.task)
  File "/home/airflow/.local/lib/python3.7/site-packages/airflow/models/taskinstance.py", line 1511, in _execute_task
    result = execute_callable(context=context)
  File "/home/airflow/.local/lib/python3.7/site-packages/airflow/operators/bash.py", line 182, in execute
    cwd=self.cwd,
  File "/home/airflow/.local/lib/python3.7/site-packages/airflow/hooks/subprocess.py", line 87, in run_command
    for raw_line in iter(self.sub_process.stdout.readline, b''):
  File "/home/airflow/.local/lib/python3.7/site-packages/airflow/models/taskinstance.py", line 1410, in signal_handler
    raise AirflowException("Task received SIGTERM signal")
airflow.exceptions.AirflowException: Task received SIGTERM signal
[2022-04-13 22:15:18,090] {process_utils.py:70} INFO - Process psutil.Process(pid=6786, status='terminated', exitcode=1, started='21:53:55') (6786) terminated with exit code 1
[2022-04-13 22:15:18,092] {process_utils.py:70} INFO - Process psutil.Process(pid=6787, status='terminated', started='21:53:55') (6787) terminated with exit code None
