[2022-04-11 20:06:23,737] {taskinstance.py:1032} INFO - Dependencies all met for <TaskInstance: data_ingestion_gcs_dag.download_dataset_task manual__2022-04-11T20:06:20.625199+00:00 [queued]>
[2022-04-11 20:06:23,751] {taskinstance.py:1032} INFO - Dependencies all met for <TaskInstance: data_ingestion_gcs_dag.download_dataset_task manual__2022-04-11T20:06:20.625199+00:00 [queued]>
[2022-04-11 20:06:23,751] {taskinstance.py:1238} INFO - 
--------------------------------------------------------------------------------
[2022-04-11 20:06:23,752] {taskinstance.py:1239} INFO - Starting attempt 1 of 2
[2022-04-11 20:06:23,752] {taskinstance.py:1240} INFO - 
--------------------------------------------------------------------------------
[2022-04-11 20:06:23,768] {taskinstance.py:1259} INFO - Executing <Task(BashOperator): download_dataset_task> on 2022-04-11 20:06:20.625199+00:00
[2022-04-11 20:06:23,779] {standard_task_runner.py:52} INFO - Started process 8205 to run task
[2022-04-11 20:06:23,783] {standard_task_runner.py:76} INFO - Running: ['***', 'tasks', 'run', 'data_ingestion_gcs_dag', 'download_dataset_task', 'manual__2022-04-11T20:06:20.625199+00:00', '--job-id', '16', '--raw', '--subdir', 'DAGS_FOLDER/data_ingestion_gcs_dag.py', '--cfg-path', '/tmp/tmpy_cwg_t6', '--error-file', '/tmp/tmp9mjtt7od']
[2022-04-11 20:06:23,785] {standard_task_runner.py:77} INFO - Job 16: Subtask download_dataset_task
[2022-04-11 20:06:23,869] {logging_mixin.py:109} INFO - Running <TaskInstance: data_ingestion_gcs_dag.download_dataset_task manual__2022-04-11T20:06:20.625199+00:00 [running]> on host 8d956c578a40
[2022-04-11 20:06:23,932] {taskinstance.py:1426} INFO - Exporting the following env vars:
AIRFLOW_CTX_DAG_OWNER=***
AIRFLOW_CTX_DAG_ID=data_ingestion_gcs_dag
AIRFLOW_CTX_TASK_ID=download_dataset_task
AIRFLOW_CTX_EXECUTION_DATE=2022-04-11T20:06:20.625199+00:00
AIRFLOW_CTX_DAG_RUN_ID=manual__2022-04-11T20:06:20.625199+00:00
[2022-04-11 20:06:23,933] {subprocess.py:62} INFO - Tmp dir root location: 
 /tmp
[2022-04-11 20:06:23,935] {subprocess.py:74} INFO - Running command: ['bash', '-c', 'curl -sSL https://s3.amazonaws.com/nyc-tlc/trip+data/yellow_tripdata_2021-01.csv > /opt/***/yellow_tripdata_2021-01.csv']
[2022-04-11 20:06:23,956] {subprocess.py:85} INFO - Output:
[2022-04-11 20:11:13,258] {subprocess.py:89} INFO - curl: (18) transfer closed with 103256310 bytes remaining to read
[2022-04-11 20:11:13,260] {subprocess.py:93} INFO - Command exited with return code 18
[2022-04-11 20:11:13,274] {taskinstance.py:1700} ERROR - Task failed with exception
Traceback (most recent call last):
  File "/home/airflow/.local/lib/python3.7/site-packages/airflow/models/taskinstance.py", line 1329, in _run_raw_task
    self._execute_task_with_callbacks(context)
  File "/home/airflow/.local/lib/python3.7/site-packages/airflow/models/taskinstance.py", line 1455, in _execute_task_with_callbacks
    result = self._execute_task(context, self.task)
  File "/home/airflow/.local/lib/python3.7/site-packages/airflow/models/taskinstance.py", line 1511, in _execute_task
    result = execute_callable(context=context)
  File "/home/airflow/.local/lib/python3.7/site-packages/airflow/operators/bash.py", line 188, in execute
    f'Bash command failed. The command returned a non-zero exit code {result.exit_code}.'
airflow.exceptions.AirflowException: Bash command failed. The command returned a non-zero exit code 18.
[2022-04-11 20:11:13,283] {taskinstance.py:1277} INFO - Marking task as UP_FOR_RETRY. dag_id=data_ingestion_gcs_dag, task_id=download_dataset_task, execution_date=20220411T200620, start_date=20220411T200623, end_date=20220411T201113
[2022-04-11 20:11:13,303] {standard_task_runner.py:92} ERROR - Failed to execute job 16 for task download_dataset_task
Traceback (most recent call last):
  File "/home/airflow/.local/lib/python3.7/site-packages/airflow/task/task_runner/standard_task_runner.py", line 85, in _start_by_fork
    args.func(args, dag=self.dag)
  File "/home/airflow/.local/lib/python3.7/site-packages/airflow/cli/cli_parser.py", line 48, in command
    return func(*args, **kwargs)
  File "/home/airflow/.local/lib/python3.7/site-packages/airflow/utils/cli.py", line 92, in wrapper
    return f(*args, **kwargs)
  File "/home/airflow/.local/lib/python3.7/site-packages/airflow/cli/commands/task_command.py", line 298, in task_run
    _run_task_by_selected_method(args, dag, ti)
  File "/home/airflow/.local/lib/python3.7/site-packages/airflow/cli/commands/task_command.py", line 107, in _run_task_by_selected_method
    _run_raw_task(args, ti)
  File "/home/airflow/.local/lib/python3.7/site-packages/airflow/cli/commands/task_command.py", line 184, in _run_raw_task
    error_file=args.error_file,
  File "/home/airflow/.local/lib/python3.7/site-packages/airflow/utils/session.py", line 70, in wrapper
    return func(*args, session=session, **kwargs)
  File "/home/airflow/.local/lib/python3.7/site-packages/airflow/models/taskinstance.py", line 1329, in _run_raw_task
    self._execute_task_with_callbacks(context)
  File "/home/airflow/.local/lib/python3.7/site-packages/airflow/models/taskinstance.py", line 1455, in _execute_task_with_callbacks
    result = self._execute_task(context, self.task)
  File "/home/airflow/.local/lib/python3.7/site-packages/airflow/models/taskinstance.py", line 1511, in _execute_task
    result = execute_callable(context=context)
  File "/home/airflow/.local/lib/python3.7/site-packages/airflow/operators/bash.py", line 188, in execute
    f'Bash command failed. The command returned a non-zero exit code {result.exit_code}.'
airflow.exceptions.AirflowException: Bash command failed. The command returned a non-zero exit code 18.
[2022-04-11 20:11:13,334] {local_task_job.py:154} INFO - Task exited with return code 1
[2022-04-11 20:11:13,363] {local_task_job.py:264} INFO - 0 downstream tasks scheduled from follow-on schedule check
