[2022-04-16 16:56:22,073] {taskinstance.py:1032} INFO - Dependencies all met for <TaskInstance: live_coded_gcs_2_bg_dag.gcs_2_bq_ext_task manual__2022-04-15T21:59:36.021929+00:00 [queued]>
[2022-04-16 16:56:22,103] {taskinstance.py:1032} INFO - Dependencies all met for <TaskInstance: live_coded_gcs_2_bg_dag.gcs_2_bq_ext_task manual__2022-04-15T21:59:36.021929+00:00 [queued]>
[2022-04-16 16:56:22,104] {taskinstance.py:1238} INFO - 
--------------------------------------------------------------------------------
[2022-04-16 16:56:22,106] {taskinstance.py:1239} INFO - Starting attempt 1 of 2
[2022-04-16 16:56:22,107] {taskinstance.py:1240} INFO - 
--------------------------------------------------------------------------------
[2022-04-16 16:56:22,138] {taskinstance.py:1259} INFO - Executing <Task(BigQueryCreateExternalTableOperator): gcs_2_bq_ext_task> on 2022-04-15 21:59:36.021929+00:00
[2022-04-16 16:56:22,146] {standard_task_runner.py:52} INFO - Started process 232 to run task
[2022-04-16 16:56:22,152] {standard_task_runner.py:76} INFO - Running: ['***', 'tasks', 'run', 'live_coded_gcs_2_bg_dag', 'gcs_2_bq_ext_task', 'manual__2022-04-15T21:59:36.021929+00:00', '--job-id', '2131', '--raw', '--subdir', 'DAGS_FOLDER/gcs_2_bq_dag.py', '--cfg-path', '/tmp/tmp01vxlrr2', '--error-file', '/tmp/tmptfxno9za']
[2022-04-16 16:56:22,157] {standard_task_runner.py:77} INFO - Job 2131: Subtask gcs_2_bq_ext_task
[2022-04-16 16:56:22,259] {logging_mixin.py:109} INFO - Running <TaskInstance: live_coded_gcs_2_bg_dag.gcs_2_bq_ext_task manual__2022-04-15T21:59:36.021929+00:00 [running]> on host 0f0253b9972c
[2022-04-16 16:56:22,379] {taskinstance.py:1426} INFO - Exporting the following env vars:
AIRFLOW_CTX_DAG_OWNER=***
AIRFLOW_CTX_DAG_ID=live_coded_gcs_2_bg_dag
AIRFLOW_CTX_TASK_ID=gcs_2_bq_ext_task
AIRFLOW_CTX_EXECUTION_DATE=2022-04-15T21:59:36.021929+00:00
AIRFLOW_CTX_DAG_RUN_ID=manual__2022-04-15T21:59:36.021929+00:00
[2022-04-16 16:56:22,382] {crypto.py:82} WARNING - empty cryptography key - values will not be stored encrypted.
[2022-04-16 16:56:26,840] {taskinstance.py:1700} ERROR - Task failed with exception
Traceback (most recent call last):
  File "/home/airflow/.local/lib/python3.7/site-packages/airflow/models/taskinstance.py", line 1329, in _run_raw_task
    self._execute_task_with_callbacks(context)
  File "/home/airflow/.local/lib/python3.7/site-packages/airflow/models/taskinstance.py", line 1455, in _execute_task_with_callbacks
    result = self._execute_task(context, self.task)
  File "/home/airflow/.local/lib/python3.7/site-packages/airflow/models/taskinstance.py", line 1511, in _execute_task
    result = execute_callable(context=context)
  File "/home/airflow/.local/lib/python3.7/site-packages/airflow/providers/google/cloud/operators/bigquery.py", line 1196, in execute
    table_resource=self.table_resource,
  File "/home/airflow/.local/lib/python3.7/site-packages/airflow/providers/google/common/hooks/base_google.py", line 430, in inner_wrapper
    return func(self, *args, **kwargs)
  File "/home/airflow/.local/lib/python3.7/site-packages/airflow/providers/google/cloud/hooks/bigquery.py", line 408, in create_empty_table
    table=table, exists_ok=exists_ok, retry=retry
  File "/home/airflow/.local/lib/python3.7/site-packages/google/cloud/bigquery/client.py", line 755, in create_table
    timeout=timeout,
  File "/home/airflow/.local/lib/python3.7/site-packages/google/cloud/bigquery/client.py", line 782, in _call_api
    return call()
  File "/home/airflow/.local/lib/python3.7/site-packages/google/api_core/retry.py", line 291, in retry_wrapped_func
    on_error=on_error,
  File "/home/airflow/.local/lib/python3.7/site-packages/google/api_core/retry.py", line 189, in retry_target
    return target()
  File "/home/airflow/.local/lib/python3.7/site-packages/google/cloud/_http.py", line 484, in api_request
    raise exceptions.from_http_response(response)
google.api_core.exceptions.NotFound: 404 POST https://bigquery.googleapis.com/bigquery/v2/projects/disco-abacus-332810/datasets/trips_data_all/tables?prettyPrint=false: Not found: Dataset disco-abacus-332810:trips_data_all
[2022-04-16 16:56:26,896] {taskinstance.py:1277} INFO - Marking task as UP_FOR_RETRY. dag_id=live_coded_gcs_2_bg_dag, task_id=gcs_2_bq_ext_task, execution_date=20220415T215936, start_date=20220416T165622, end_date=20220416T165626
[2022-04-16 16:56:26,935] {standard_task_runner.py:92} ERROR - Failed to execute job 2131 for task gcs_2_bq_ext_task
Traceback (most recent call last):
  File "/home/airflow/.local/lib/python3.7/site-packages/airflow/task/task_runner/standard_task_runner.py", line 85, in _start_by_fork
    args.func(args, dag=self.dag)
  File "/home/airflow/.local/lib/python3.7/site-packages/airflow/cli/cli_parser.py", line 48, in command
    return func(*args, **kwargs)
  File "/home/airflow/.local/lib/python3.7/site-packages/airflow/utils/cli.py", line 92, in wrapper
    return f(*args, **kwargs)
  File "/home/airflow/.local/lib/python3.7/site-packages/airflow/cli/commands/task_command.py", line 298, in task_run
    _run_task_by_selected_method(args, dag, ti)
  File "/home/airflow/.local/lib/python3.7/site-packages/airflow/cli/commands/task_command.py", line 107, in _run_task_by_selected_method
    _run_raw_task(args, ti)
  File "/home/airflow/.local/lib/python3.7/site-packages/airflow/cli/commands/task_command.py", line 184, in _run_raw_task
    error_file=args.error_file,
  File "/home/airflow/.local/lib/python3.7/site-packages/airflow/utils/session.py", line 70, in wrapper
    return func(*args, session=session, **kwargs)
  File "/home/airflow/.local/lib/python3.7/site-packages/airflow/models/taskinstance.py", line 1329, in _run_raw_task
    self._execute_task_with_callbacks(context)
  File "/home/airflow/.local/lib/python3.7/site-packages/airflow/models/taskinstance.py", line 1455, in _execute_task_with_callbacks
    result = self._execute_task(context, self.task)
  File "/home/airflow/.local/lib/python3.7/site-packages/airflow/models/taskinstance.py", line 1511, in _execute_task
    result = execute_callable(context=context)
  File "/home/airflow/.local/lib/python3.7/site-packages/airflow/providers/google/cloud/operators/bigquery.py", line 1196, in execute
    table_resource=self.table_resource,
  File "/home/airflow/.local/lib/python3.7/site-packages/airflow/providers/google/common/hooks/base_google.py", line 430, in inner_wrapper
    return func(self, *args, **kwargs)
  File "/home/airflow/.local/lib/python3.7/site-packages/airflow/providers/google/cloud/hooks/bigquery.py", line 408, in create_empty_table
    table=table, exists_ok=exists_ok, retry=retry
  File "/home/airflow/.local/lib/python3.7/site-packages/google/cloud/bigquery/client.py", line 755, in create_table
    timeout=timeout,
  File "/home/airflow/.local/lib/python3.7/site-packages/google/cloud/bigquery/client.py", line 782, in _call_api
    return call()
  File "/home/airflow/.local/lib/python3.7/site-packages/google/api_core/retry.py", line 291, in retry_wrapped_func
    on_error=on_error,
  File "/home/airflow/.local/lib/python3.7/site-packages/google/api_core/retry.py", line 189, in retry_target
    return target()
  File "/home/airflow/.local/lib/python3.7/site-packages/google/cloud/_http.py", line 484, in api_request
    raise exceptions.from_http_response(response)
google.api_core.exceptions.NotFound: 404 POST https://bigquery.googleapis.com/bigquery/v2/projects/disco-abacus-332810/datasets/trips_data_all/tables?prettyPrint=false: Not found: Dataset disco-abacus-332810:trips_data_all
[2022-04-16 16:56:26,958] {local_task_job.py:154} INFO - Task exited with return code 1
[2022-04-16 16:56:27,052] {local_task_job.py:264} INFO - 0 downstream tasks scheduled from follow-on schedule check
